<mujoco model="ur5">
    <compiler angle="radian" meshdir="meshes_mujoco/" />
    <size njmax="500" nconmax="100" />
    <asset>
        <mesh name="base_visual" file="base_visual.stl" />
        <mesh name="base" file="base.stl" />
        <mesh name="shoulder_visual" file="shoulder_visual.stl" />
        <mesh name="shoulder" file="shoulder.stl" />
        <mesh name="upperarm_visual" file="upperarm_visual.stl" />
        <mesh name="upperarm" file="upperarm.stl" />
        <mesh name="forearm_visual" file="forearm_visual.stl" />
        <mesh name="forearm" file="forearm.stl" />
        <mesh name="wrist1_visual" file="wrist1_visual.stl" />
        <mesh name="wrist1" file="wrist1.stl" />
        <mesh name="wrist2_visual" file="wrist2_visual.stl" />
        <mesh name="wrist2" file="wrist2.stl" />
        <mesh name="wrist3_visual" file="wrist3_visual.stl" />
        <mesh name="wrist3" file="wrist3.stl" />

        <!--Textures-->
        <texture name="floor_tex"   type="2d"       builtin="checker" rgb1=".2 .3 .4" rgb2=".1 .2 .3" width="100" height="100" />
        <!--Materials-->
        <material name='floor_mat'      texture="floor_tex"  shininess="0.8" texrepeat="10 10" specular="0.7"  reflectance="0.5" />
        <material name="bench_mat"      texture="floor_tex"   shininess="0.1" specular="0.5" reflectance="0.2"/>
    </asset>
    <worldbody>
        <!--Lighting parameters-->
        <light name="light3" mode="targetbody" target="box_link" directional="true" pos="1 1 3" />

        <!--Floor Property-->
        <geom name='floor' material="floor_mat" pos='0 0 0' size='2.5 2.5 0.1'  type='plane' />

        <body name="box_link" pos="0 0 0.435">
            <geom size="1.0 .8 .435" type="box" material="bench_mat"/>
            <inertial pos="0 0 0" mass="1000" diaginertia="0 0 0" />

            <body name="base_link" pos="0 -0.4 0.435">
                <inertial pos="0 0 0" quat="0.5 0.5 -0.5 0.5" mass="4" diaginertia="0.0072 0.00443333 0.00443333" />
                <geom quat="0 0 0 1" type="mesh" contype="0" conaffinity="0" group="1" rgba="0.7 0.7 0.7 1" mesh="base_visual" />
                <geom quat="0 0 0 1" type="mesh" rgba="0.7 0.7 0.7 1" mesh="base" />
                <body name="shoulder_link" pos="0 0 0.089159" quat="0 0 0 1">
                    <inertial pos="0 0 0" mass="3.7" diaginertia="0.0149724 0.0149724 0.0104063" />
                    <joint name="shoulder_pan_joint" pos="0 0 0" axis="0 0 1" limited="true" range="-3.14159 3.14159" />
                    <geom quat="0 0 0 1" type="mesh" contype="0" conaffinity="0" group="1" rgba="0.7 0.7 0.7 1" mesh="shoulder_visual" />
                    <geom quat="0 0 0 1" type="mesh" rgba="0.7 0.7 0.7 1" mesh="shoulder" />
                    <body name="upper_arm_link" pos="0 0 0" quat="0.707107 0.707107 0 0">
                        <inertial pos="-0.2125 0 0.136" quat="0.707107 0 0.707107 0" mass="8.393" diaginertia="0.133886 0.133886 0.0151074" />
                        <joint name="shoulder_lift_joint" pos="0 0 0" axis="0 0 1" limited="true" range="-3.14159 3.14159" />
                        <geom pos="0 0 0.136" quat="0.5 0.5 -0.5 -0.5" type="mesh" contype="0" conaffinity="0" group="1" rgba="0.7 0.7 0.7 1" mesh="upperarm_visual" />
                        <geom pos="0 0 0.136" quat="0.5 0.5 -0.5 -0.5" type="mesh" rgba="0.7 0.7 0.7 1" mesh="upperarm" />
                        <body name="forearm_link" pos="-0.425 0 0">
                            <inertial pos="-0.2125 0 0.0165" quat="0.707107 0 0.707107 0" mass="2.275" diaginertia="0.0312168 0.0312168 0.004095" />
                            <joint name="elbow_joint" pos="0 0 0" axis="0 0 1" limited="true" range="-3.14159 3.14159" />
                            <geom pos="0 0 0.0165" quat="0.5 0.5 -0.5 -0.5" type="mesh" contype="0" conaffinity="0" group="1" rgba="0.7 0.7 0.7 1" mesh="forearm_visual" />
                            <geom pos="0 0 0.0165" quat="0.5 0.5 -0.5 -0.5" type="mesh" rgba="0.7 0.7 0.7 1" mesh="forearm" />
                            <body name="wrist_1_link" pos="-0.39225 0 0.10915">
                                <inertial pos="0 0 0" quat="0.5 0.5 -0.5 0.5" mass="1.219" diaginertia="0.00342844 0.00262426 0.00262426" />
                                <joint name="wrist_1_joint" pos="0 0 0" axis="0 0 1" limited="true" range="-3.14159 3.14159" />
                                <geom pos="0 0 -0.093" quat="0.707107 0.707107 0 0" type="mesh" contype="0" conaffinity="0" group="1" rgba="0.7 0.7 0.7 1" mesh="wrist1_visual" />
                                <geom pos="0 0 -0.093" quat="0.707107 0.707107 0 0" type="mesh" rgba="0.7 0.7 0.7 1" mesh="wrist1" />
                                <body name="wrist_2_link" pos="0 -0.09465 -1.9413e-11" quat="0.707107 0.707107 0 0">
                                    <inertial pos="0 0 0" quat="0.5 0.5 -0.5 0.5" mass="1.219" diaginertia="0.0021942 0.00178515 0.00178515" />
                                    <joint name="wrist_2_joint" pos="0 0 0" axis="0 0 1" limited="true" range="-3.14159 3.14159" />
                                    <geom pos="0 0 -0.095" type="mesh" contype="0" conaffinity="0" group="1" rgba="0.7 0.7 0.7 1" mesh="wrist2_visual" />
                                    <geom pos="0 0 -0.095" type="mesh" rgba="0.7 0.7 0.7 1" mesh="wrist2" />
                                    <body name="wrist_3_link" pos="0 0.0823 -1.688e-11" quat="0.707107 -0.707107 0 0">
                                        <inertial pos="0 0 -0.0152222" quat="0.5 0.5 -0.5 0.5" mass="0.1889" diaginertia="0.000132134 8.06688e-05 8.06688e-05" />
                                        <joint name="wrist_3_joint" pos="0 0 0" axis="0 0 1" limited="true" range="-3.14159 3.14159" />
                                        <geom pos="0 0 -0.0818" quat="0.707107 0.707107 0 0" type="mesh" contype="0" conaffinity="0" group="1" rgba="0.7 0.7 0.7 1" mesh="wrist3_visual" />
                                        <geom pos="0 0 -0.0823" quat="0.707107 0.707107 0 0" type="mesh" rgba="0.7 0.7 0.7 1" mesh="wrist3" />
                                        <geom size="0.005 0.005 0.005" pos="0 0 -0.01" quat="0.5 0.5 -0.5 0.5" type="box" />
                                    </body>
                                </body>
                            </body>
                        </body>
                    </body>
                </body>
            </body>
        </body>
    </worldbody>

    <!--ACTUATORS-->
    <actuator>
        <!--UR5-->
        <motor name='shoulder_pan_T' ctrllimited="true" ctrlrange="-2 2" joint='shoulder_pan_joint' gear="101"/> <!--range -150 150-->
        <motor name='shoulder_lift_T' ctrllimited="true" ctrlrange="-2 2" joint='shoulder_lift_joint' gear="101"/>
        <motor name='forearm_T' ctrllimited="true" ctrlrange="-2 2" joint='elbow_joint' gear="101" />
        <motor name='wrist_1_T' ctrllimited="true" ctrlrange="-1 1" joint='wrist_1_joint' gear="101"/>  <!--range -28 28-->
        <motor name='wrist_2_T' ctrllimited="true" ctrlrange="-1 1" joint='wrist_2_joint' gear="101"/>
        <motor name='wrist_3_T' ctrllimited="true" ctrlrange="-1 1" joint='wrist_3_joint' gear="101"/>
    </actuator>
</mujoco>
